Workbook
Name Health_Expense: Validation!$Q$2:$Q$5
Name Bills_Utilities_Expense: Validation!$O$2:$O$7
Name AllCategoriesSimple: Settings!$M$2:$M$16
Name BlankList: Validation!$D$2
Name AllSubcategoriesSimple: Settings!$N$2:$N$59
Name Shopping_Expense: Validation!$P$2:$P$5
Name MonthOptions: Validation!$H$2:$H$13
Name Personal_Expense: Validation!$S$2:$S$5
Name Types: Validation!$G$2:$G$4
Name FormType: 'Add Transaction'!$C$6
Name IncomeCategories: Validation!$B$2:$B$6
Name FormPaymentMethod: 'Add Transaction'!$C$13
Name Salary_Income: Validation!$V$2:$V$3
Name Family_Home_Expense: Validation!$T$2:$T$4
Name YearOptions: Validation!$J$2
Name FormAccount: #REF!
Name WeekOptions: Validation!$K$2:$K$367
Name FormDescription: 'Add Transaction'!$C$12
Name FormSubcategory: 'Add Transaction'!$C$11
Name FormAmount: 'Add Transaction'!$C$7
Name Transport_Expense: Validation!$N$2:$N$6
Name FormCategory: 'Add Transaction'!$C$10
Name TransferOnly: Validation!$C$2
Name ExpenseCategories: Validation!$A$2:$A$10
Name PaymentMethods: Validation!$E$2:$E$6
Name QuarterOptions: Validation!$I$2:$I$5
Name Other_Income_Income: Validation!$Z$2
Name Gifts_Income: Validation!$X$2
Name Accounts: Validation!$F$2:$F$6
Name Entertainment_Expense: Validation!$R$2:$R$5
Name Refunds_Income: Validation!$Y$2:$Y$3
Name Food_Drink_Expense: Validation!$M$2:$M$5
Name FormDate: 'Add Transaction'!$C$5
Name Other_Expense: Validation!$U$2:$U$4
Name Side_Income_Income: Validation!$W$2:$W$3

Sheet Add Transaction
B2: Add Transaction
B3: Enter one transaction here, then use the script/menu to add it to the Transactions tab.
B5: Date | C5: 46146 | E5: Quick check
B6: Type | C6: Expense | E6: Date, Type, Amount, Category, Payment Method, and Account should be filled.
B7: Amount (GHS) | E7: Transfers should use Type = Transfer and Category = Transfer.
B8: Tips (GHS)
B9: Category | C9: Food Drink | E9: Amounts should always be positive. | H9: =IFERROR(__xludf.DUMMYFUNCTION("IF($C$6=""Expense"",UNIQUE(FILTER(Settings!A2:A999,Settings!A2:A999<>"""")),IF($C$6=""Income"",UNIQUE(FILTER(Settings!C2:C999,Settings!C2:C999<>"""")),""Transfer""))"),"Food Drink") -> Food Drink | I9: =IFERROR(__xludf.DUMMYFUNCTION("IF($C$6=""Expense"",FILTER(Settings!B2:B999,Settings!A2:A999=$C$9),IF($C$6=""Income"",FILTER(Settings!D2:D999,Settings!C2:C999=$C$9),""""))"),"Groceries") -> Groceries
B10: Subcategory | C10: Groceries | E10: After adding, the script clears the form except Date and Type. | H10: =IFERROR(__xludf.DUMMYFUNCTION("""COMPUTED_VALUE"""),"Transport") -> Transport | I10: =IFERROR(__xludf.DUMMYFUNCTION("""COMPUTED_VALUE"""),"Restaurants") -> Restaurants
B11: Description | E11: If subcategory does not refresh immediately, choose the category again or run Spending Tracker > Refresh form dropdowns. | H11: =IFERROR(__xludf.DUMMYFUNCTION("""COMPUTED_VALUE"""),"Investment") -> Investment | I11: =IFERROR(__xludf.DUMMYFUNCTION("""COMPUTED_VALUE"""),"Takeaway") -> Takeaway
B12: Payment Method | H12: =IFERROR(__xludf.DUMMYFUNCTION("""COMPUTED_VALUE"""),"Bills Utilities") -> Bills Utilities | I12: =IFERROR(__xludf.DUMMYFUNCTION("""COMPUTED_VALUE"""),"Coffee Snacks") -> Coffee Snacks
B13: Account | H13: =IFERROR(__xludf.DUMMYFUNCTION("""COMPUTED_VALUE"""),"Shopping") -> Shopping
H14: =IFERROR(__xludf.DUMMYFUNCTION("""COMPUTED_VALUE"""),"Health") -> Health
B15: ADD TRANSACTION | H15: =IFERROR(__xludf.DUMMYFUNCTION("""COMPUTED_VALUE"""),"Entertainment") -> Entertainment
H16: =IFERROR(__xludf.DUMMYFUNCTION("""COMPUTED_VALUE"""),"Personal") -> Personal
H17: =IFERROR(__xludf.DUMMYFUNCTION("""COMPUTED_VALUE"""),"Family") -> Family
H18: =IFERROR(__xludf.DUMMYFUNCTION("""COMPUTED_VALUE"""),"Extended Family") -> Extended Family
H19: =IFERROR(__xludf.DUMMYFUNCTION("""COMPUTED_VALUE"""),"Loan Repayment") -> Loan Repayment
H20: =IFERROR(__xludf.DUMMYFUNCTION("""COMPUTED_VALUE"""),"Charity") -> Charity
H21: =IFERROR(__xludf.DUMMYFUNCTION("""COMPUTED_VALUE"""),"Other") -> Other

Sheet Settings
A1: Expense Category | B1: Expense Subcategory | C1: Income Category | D1: Income Subcategory | E1: Payment Method | F1: Account | G1: Type | H1: Month | I1: Quarter | J1: Year | L1: How to use | M1: Dropdown Category List | N1: Dropdown Subcategory List
A2: Food Drink | B2: Groceries | C2: Salary | D2: Peswa | E2: Cash | F2: Stanbic Bank | G2: Expense | H2: Jan | I2: Q1 | J2: 2024 | L2: 1. Enter every transaction on the Transactions tab. | M2: Food Drink | N2: Groceries
A3: Food Drink | B3: Restaurants | C3: Salary | D3: Rising | E3: Mobile Money | F3: MoMo Wallet | G3: Income | H3: Feb | I3: Q2 | J3: 2025 | L3: 2. Amounts should always be positive. Use Type to mark Expense, Income, or Transfer. | M3: Transport | N3: Main job
A4: Food Drink | B4: Takeaway | C4: Side Income | D4: Freelance | E4: Card | F4: Cash | G4: Transfer | H4: Mar | I4: Q3 | J4: 2026 | L4: 3. Transfers are counted separately and do not count as spending. | M4: Bills Utilities | N4: Restaurants
A5: Food Drink | B5: Coffee Snacks | C5: Side Income | D5: Business | E5: Bank Transfer | F5: Other | H5: Apr | I5: Q4 | J5: 2027 | L5: 4. Edit categories, payment methods, and accounts on this Settings tab. | M5: Shopping | N5: Bonus
A6: Transport | B6: Fuel | C6: Gifts | D6: Family Friends | E6: Other | H6: May | J6: 2028 | L6: 5. Use Dashboard to choose a week, month, quarter, or year. | M6: Health | N6: Takeaway
A7: Transport | B7: Taxi Trotro | C7: Refunds | D7: Purchase refund | H7: Jun | J7: 2029 | M7: Entertainment | N7: Freelance
A8: Transport | B8: Uber Bolt | C8: Refunds | D8: Reimbursement | H8: Jul | J8: 2030 | M8: Personal | N8: Coffee Snacks
A9: Transport | B9: Vehicle maintenance | C9: Other Income | D9: Other | H9: Aug | M9: Family Home | N9: Business
A10: Transport | B10: Parking | H10: Sep | M10: Other | N10: Fuel
A11: Transport | B11: Car Wash | H11: Oct | M11: Salary | N11: Family Friends
A12: Investment | B12: Land | H12: Nov | M12: Side Income | N12: Taxi Trotro
A13: Bills Utilities | B13: Rent | H13: Dec | M13: Gifts | N13: Purchase refund
A14: Bills Utilities | B14: Electricity | M14: Refunds | N14: Uber Bolt
A15: Bills Utilities | B15: Water | M15: Other Income | N15: Reimbursement
A16: Bills Utilities | B16: Internet | M16: Transfer | N16: Vehicle maintenance
A17: Bills Utilities | B17: Phone bill | N17: Other
A18: Bills Utilities | B18: Gas | N18: Parking
A19: Shopping | B19: Clothing | N19: Rent
A20: Shopping | B20: Electronics | M20: Note: These simple lists feed the Transactions dropdowns.
A21: Shopping | B21: Home goods | N21: Water
A22: Shopping | B22: Personal items | N22: Internet
A23: Health | B23: Pharmacy | N23: Phone bill
A24: Health | B24: Doctor Clinic | N24: Gas
A25: Health | B25: Insurance | N25: Clothing
A26: Health | B26: Fitness | N26: Electronics
A27: Entertainment | B27: Streaming | N27: Home goods
A28: Entertainment | B28: Events Outings | N28: Personal items
A29: Entertainment | B29: Movies | N29: Pharmacy
A30: Entertainment | B30: Hobbies | N30: Doctor Clinic
A31: Personal | B31: Barbering | N31: Insurance
A32: Personal | B32: Gifts | N32: Streaming
... A34: Family | B34: Beb | N34: Movies
A35: Family | B35: Ibrahim
A36: Family | B36: Abdur-Rahman
A37: Extended Family | B37: Dedei
A38: Extended Family | B38: Odarkor
A39: Extended Family | B39: Koshie
A40: Extended Family | B40: Mommy
A41: Extended Family | B41: Aryee
...

Sheet Transactions
A1: Row ID | B1: Date | C1: Type | D1: Amount (GHS) | E1: Tips (GHS) | F1: Category | G1: Subcategory | H1: Description | I1: Payment Method | J1: Account
A2: 1 | B2: 46201 | C2: Income | D2: 23000 | F2: Salary | G2: Main job | H2: June salary | I2: Bank Transfer | J2: Stanbic Bank
A3: 2 | B3: 46201 | C3: Income | D3: 7000.47 | F3: Salary | G3: Main job | H3: Stanbic initial balance | I3: Bank Transfer | J3: Stanbic Bank
A4: 3 | B4: 46201 | C4: Income | D4: 1042 | F4: Salary | G4: Main job | H4: Initial Cash | I4: Cash | J4: Cash
A5: 4 | B5: 46201 | C5: Expense | D5: 200 | E5: 10 | F5: Transport | G5: Fuel | H5: Fuel for Generator | I5: Cash | J5: Cash
A6: 5 | B6: 46202 | C6: Expense | D6: 100 | E6: 0 | F6: Extended Family | G6: Auntie (Maxwell) | I6: Cash | J6: Cash
A7: 6 | B7: 46202 | C7: Expense | D7: 53 | E7: 0 | F7: Food Drink | G7: Groceries | H7: Bread and biscuit | I7: Cash | J7: Cash
A8: 7 | B8: 46203 | C8: Expense | D8: 300 | E8: 0 | F8: Extended Family | G8: Dedei | H8: Buying corn husk | I8: Cash | J8: Cash
A9: 8 | B9: 46203 | C9: Expense | D9: 11599 | E9: 0 | F9: Loan Repayment | G9: Beb | H9: Repayment of loan | I9: Bank Transfer | J9: Stanbic Bank
A10: 9 | B10: 46203 | C10: Transfer | D10: 10611 | F10: Transfer | I10: Bank Transfer | J10: Cash
A11: 10 | B11: 46204 | C11: Expense | D11: 200 | E11: 0 | F11: Other | G11: ⁠‌‌‌‌‌‌‌‌‌‍‌‌‍‍‍‌‌‌‌‌‌‌‌‌‌‍‍‌‌‌‌‍‌‌‌‌‌‌‌‌‌‍‍‌‍‍‍‌‌‌‌‌‌‌‌‌‌‍‍‌‌‌‌‍‌‌‌‌‌‌‌‌‌‌‍‌‌‌‌‌‌‌‌‌‌‌‌‌‌‍‌‌‌‌‌‍‌‌‌‌‌‌‌‌‌‍‍‌‌‍‌‌‌‌‌‌‌‌‌‌‌‍‍‌‍‌‍‌‌‌‌‌‌‌‌‌‌‍‍‌‍‍‍‍‌‌‌‌‌‌‌‌‌‍‍‌‌‌‌‍⁤ | I11: Cash | J11: Cash
A12: 11 | B12: 46204 | C12: Expense | D12: 50 | E12: 0 | F12: Other | G12: Charity | H12: Ebenezer Auntie teacher | I12: Cash | J12: Cash
A13: 12 | B13: 46146 | C13: Expense | D13: 1000 | E13: 0 | F13: Extended Family | G13: Dedei | H13: Dr Safo last payment | I13: Mobile Money | J13: MoMo Wallet
A14: 13 | B14: 46146 | C14: Expense | D14: 20 | E14: 0 | F14: Extended Family | G14: Koshie | H14: Haircut | I14: Cash | J14: Cash
A15: 14 | B15: 46146 | C15: Expense | D15: 20 | E15: 0 | F15: Extended Family | G15: Odarkor | I15: Cash | J15: Cash
A16: 15 | B16: 46146 | C16: Expense | D16: 1000 | E16: 0 | F16: Charity | G16: Friends | H16: Mary's mother's funeral | I16: Mobile Money | J16: MoMo Wallet
A17: 16 | B17: 46146 | C17: Expense | D17: 500 | E17: 0 | F17: Other | G17: ⁠‌‌‌‌‌‌‌‌‌‍‌‌‌‍‍‌‌‌‌‌‌‌‌‌‌‍‍‌‌‌‌‍‌‌‌‌‌‌‌‌‌‍‍‍‌‍‌‍‌‌‌‌‌‌‌‌‌‍‍‍‍‌‍‌‌‌‌‌‌‌‌‌‌‍‍‌‍‌‌‍‌‌‌‌‌‌‌‌‌‍‍‌‌‌‌‍⁤ | I17: Mobile Money | J17: MoMo Wallet
A18: 17 | B18: 46146 | C18: Expense | D18: 100 | E18: 0 | F18: Extended Family | G18: Jalil | I18: Cash | J18: Cash
A19: 18 | B19: 46146 | C19: Expense | D19: 300 | E19: 0 | F19: Transport | G19: Car Wash | I19: Cash | J19: Cash
A20: 19 | B20: 46146 | C20: Expense | D20: 800 | E20: 60 | F20: Family | G20: Beb | H20: Spa Treatment | I20: Bank Transfer | J20: Stanbic Bank
A21: 20 | B21: 46146 | C21: Expense | D21: 490 | E21: 0 | F21: Family | G21: Beb | H21: Phone Case and protector | I21: Bank Transfer | J21: Stanbic Bank
A22: 21 | B22: 46146 | C22: Expense | D22: 656 | E22: 0 | F22: Family | G22: Ibrahim | H22: Bike | I22: Mobile Money | J22: MoMo Wallet
A23: 22 | B23: 46146 | C23: Expense | D23: 610 | E23: 0 | F23: Family | G23: Abdur-Rahman | H23: Bike | I23: Mobile Money | J23: MoMo Wallet
A24: 23 | B24: 46146 | C24: Expense | D24: 500 | E24: 0 | F24: Family | G24: Beb | H24: Transportation to funeral | I24: Mobile Money | J24: MoMo Wallet
A25: 24 | B25: 46146 | C25: Expense | D25: 6000 | E25: 0 | F25: Investment | G25: Land | H25: Land document part payment | I25: Cash | J25: Cash
A26: 25 | B26: 46146 | C26: Expense | D26: 75 | E26: 0 | F26: Extended Family | G26: Odarkor | H26: Feeding fee | I26: Cash | J26: Cash
A27: 26 | B27: 46146 | C27: Expense | D27: 75 | E27: 0 | F27: Extended Family | G27: Koshie | H27: Feeding fee | I27: Cash | J27: Cash
A28: 27 | B28: 46146 | C28: Expense | D28: 50 | E28: 0 | F28: Extended Family | G28: Auntie (Maxwell) | H28: Feeding Fee | I28: Cash | J28: Cash
A29: 28 | B29: 46146 | C29: Income | D29: 18847 | F29: Salary | G29: Rising | H29: June Salary | I29: Bank Transfer | J29: Stanbic Bank
A30: 29 | B30: 46146 | C30: Expense | D30: 55 | E30: 0 | F30: Food Drink | G30: Takeaway | H30: Beans | I30: Cash | J30: Cash
A31: 30 | B31: 46146 | C31: Expense | D31: 100 | E31: 0 | F31: Charity | G31: Friends | H31: Fauzia | I31: Cash | J31: Cash
A32: 31 | B32: 46146 | C32: Expense | D32: 50 | E32: 0 | F32: Charity | G32: Poor | H32: Polo's brother | I32: Cash | J32: Cash
A33: 32 | B33: 46146 | C33: Expense | D33: 500 | E33: 20 | F33: Transport | G33: Fuel | I33: Mobile Money | J33: MoMo Wallet
A34: 33 | B34: 46146 | C34: Expense | D34: 65 | E34: 0 | F34: Shopping | G34: Clothing | H34: Slippers | I34: Mobile Money | J34: Cash
A35: 34 | B35: 46146 | C35: Expense | D35: 75 | E35: 0 | F35: Family | G35: Beb | H35: Slippers | I35: Mobile Money | J35: MoMo Wallet
A36: 35 | B36: 46146 | C36: Expense | D36: 500 | E36: 0 | F36: Investment | G36: Land | H36: Police to arrest Abusua Panyin | I36: Mobile Money | J36: Cash
A37: 36 | B37: 46146 | C37: Expense | D37: 460 | E37: 0 | F37: Charity | G37: Masjid | H37: work at cemetery | I37: Mobile Money | J37: MoMo Wallet
A38: 37 | B38: 46146 | C38: Expense | D38: 20000 | E38: 0 | F38: Investment | G38: Land | H38: Payment to Mr Richard | I38: Bank Transfer | J38: Stanbic Bank
A39: 38 | B39: 46146 | C39: Expense | D39: 1000 | E39: 0 | F39: Investment | G39: Land | H39: Police to arrest Abusua Panyin | I39: Mobile Money | J39: MoMo Wallet
A40: 39 | B40: 46146 | C40: Expense | D40: 1000 | E40: 0 | F40: Extended Family | G40: Dedei | H40: Paying off debt to wood seller | I40: Bank Transfer | J40: Stanbic Bank
...

Sheet Dashboard
A1: Spending Dashboard
A2: Period Type | B2: Year | D2: Tip
A3: Year | B3: 2026 | D3: Change B2/B3/B4 to view any week, month, quarter, or year.
A4: Period | B4: Jul
A6: Start Date | B6: =IF($B$2="Week",$B$4,IF($B$2="Month",DATE($B$3,MATCH($B$4,MonthOptions,0),1),IF($B$2="Quarter",DATE($B$3,(VALUE(RIGHT($B$4,1))-1)*3+1,1),DATE($B$3,1,1)))) -> 46023
A7: End Date | B7: =IF($B$2="Week",$B$6+6,IF($B$2="Month",EOMONTH($B$6,0),IF($B$2="Quarter",EOMONTH($B$6,2),DATE($B$3,12,31)))) -> 46387
A10: Total Expenses | B10: =SUMIFS(Transactions!$D:$D,Transactions!$B:$B,">="&$B$6,Transactions!$B:$B,"<="&$B$7,Transactions!$C:$C,"Expense") +SUMIFS(Transactions!$E:$E,Transactions!$B:$B,">="&$B$6,Transactions!$B:$B,"<="&$B$7,Transactions!$C:$C,"Expense") -> 48943
A11: Total Income | B11: =SUMIFS(Transactions!$D:$D,Transactions!$B:$B,">="&$B$6,Transactions!$B:$B,"<="&$B$7,Transactions!$C:$C,"Income") -> 49889.47
A12: Total Transfers | B12: =SUMIFS(Transactions!$D:$D,Transactions!$B:$B,">="&$B$6,Transactions!$B:$B,"<="&$B$7,Transactions!$C:$C,"Transfer") -> 10611
A13: Net Cash Flow | B13: =B11-B10 -> 946.47
A16: Expense Category | B16: Amount | D16: Expense Subcategory | E16: Amount
A17: Food Drink | B17: =SUMIFS(Transactions!$D:$D,Transactions!$B:$B,">="&$B$6,Transactions!$B:$B,"<="&$B$7,Transactions!$C:$C,"Expense",Transactions!$F:$F,A17) +SUMIFS(Transactions!$E:$E,Transactions!$B:$B,">="&$B$6,Transactions!$B:$B,"<="&$B$7,Transactions!$C:$C,"Expense",Transactions!$F:$F,A17) -> 108 | D17: Groceries | E17: =SUMIFS(Transactions!$D:$D,Transactions!$B:$B,">="&$B$6,Transactions!$B:$B,"<="&$B$7,Transactions!$C:$C,"Expense",Transactions!$G:$G,D17) +SUMIFS(Transactions!$E:$E,Transactions!$B:$B,">="&$B$6,Transactions!$B:$B,"<="&$B$7,Transactions!$C:$C,"Expense",Transactions!$G:$G,D17) -> 53
A18: Transport | B18: =SUMIFS(Transactions!$D:$D,Transactions!$B:$B,">="&$B$6,Transactions!$B:$B,"<="&$B$7,Transactions!$C:$C,"Expense",Transactions!$F:$F,A18) +SUMIFS(Transactions!$E:$E,Transactions!$B:$B,">="&$B$6,Transactions!$B:$B,"<="&$B$7,Transactions!$C:$C,"Expense",Transactions!$F:$F,A18) -> 1030 | D18: Restaurants | E18: =SUMIFS(Transactions!$D:$D,Transactions!$B:$B,">="&$B$6,Transactions!$B:$B,"<="&$B$7,Transactions!$C:$C,"Expense",Transactions!$G:$G,D18) +SUMIFS(Transactions!$E:$E,Transactions!$B:$B,">="&$B$6,Transactions!$B:$B,"<="&$B$7,Transactions!$C:$C,"Expense",Transactions!$G:$G,D18) -> 0
A19: Bills Utilities | B19: =SUMIFS(Transactions!$D:$D,Transactions!$B:$B,">="&$B$6,Transactions!$B:$B,"<="&$B$7,Transactions!$C:$C,"Expense",Transactions!$F:$F,A19) +SUMIFS(Transactions!$E:$E,Transactions!$B:$B,">="&$B$6,Transactions!$B:$B,"<="&$B$7,Transactions!$C:$C,"Expense",Transactions!$F:$F,A19) -> 0 | D19: Takeaway | E19: =SUMIFS(Transactions!$D:$D,Transactions!$B:$B,">="&$B$6,Transactions!$B:$B,"<="&$B$7,Transactions!$C:$C,"Expense",Transactions!$G:$G,D19) +SUMIFS(Transactions!$E:$E,Transactions!$B:$B,">="&$B$6,Transactions!$B:$B,"<="&$B$7,Transactions!$C:$C,"Expense",Transactions!$G:$G,D19) -> 55
A20: Shopping | B20: =SUMIFS(Transactions!$D:$D,Transactions!$B:$B,">="&$B$6,Transactions!$B:$B,"<="&$B$7,Transactions!$C:$C,"Expense",Transactions!$F:$F,A20) +SUMIFS(Transactions!$E:$E,Transactions!$B:$B,">="&$B$6,Transactions!$B:$B,"<="&$B$7,Transactions!$C:$C,"Expense",Transactions!$F:$F,A20) -> 65 | D20: Coffee Snacks | E20: =SUMIFS(Transactions!$D:$D,Transactions!$B:$B,">="&$B$6,Transactions!$B:$B,"<="&$B$7,Transactions!$C:$C,"Expense",Transactions!$G:$G,D20) +SUMIFS(Transactions!$E:$E,Transactions!$B:$B,">="&$B$6,Transactions!$B:$B,"<="&$B$7,Transactions!$C:$C,"Expense",Transactions!$G:$G,D20) -> 0
A21: Health | B21: =SUMIFS(Transactions!$D:$D,Transactions!$B:$B,">="&$B$6,Transactions!$B:$B,"<="&$B$7,Transactions!$C:$C,"Expense",Transactions!$F:$F,A21) +SUMIFS(Transactions!$E:$E,Transactions!$B:$B,">="&$B$6,Transactions!$B:$B,"<="&$B$7,Transactions!$C:$C,"Expense",Transactions!$F:$F,A21) -> 0 | D21: Fuel | E21: =SUMIFS(Transactions!$D:$D,Transactions!$B:$B,">="&$B$6,Transactions!$B:$B,"<="&$B$7,Transactions!$C:$C,"Expense",Transactions!$G:$G,D21) +SUMIFS(Transactions!$E:$E,Transactions!$B:$B,">="&$B$6,Transactions!$B:$B,"<="&$B$7,Transactions!$C:$C,"Expense",Transactions!$G:$G,D21) -> 730
A22: Entertainment | B22: =SUMIFS(Transactions!$D:$D,Transactions!$B:$B,">="&$B$6,Transactions!$B:$B,"<="&$B$7,Transactions!$C:$C,"Expense",Transactions!$F:$F,A22) +SUMIFS(Transactions!$E:$E,Transactions!$B:$B,">="&$B$6,Transactions!$B:$B,"<="&$B$7,Transactions!$C:$C,"Expense",Transactions!$F:$F,A22) -> 0 | D22: Taxi Trotro | E22: =SUMIFS(Transactions!$D:$D,Transactions!$B:$B,">="&$B$6,Transactions!$B:$B,"<="&$B$7,Transactions!$C:$C,"Expense",Transactions!$G:$G,D22) +SUMIFS(Transactions!$E:$E,Transactions!$B:$B,">="&$B$6,Transactions!$B:$B,"<="&$B$7,Transactions!$C:$C,"Expense",Transactions!$G:$G,D22) -> 0
A23: Personal | B23: =SUMIFS(Transactions!$D:$D,Transactions!$B:$B,">="&$B$6,Transactions!$B:$B,"<="&$B$7,Transactions!$C:$C,"Expense",Transactions!$F:$F,A23) +SUMIFS(Transactions!$E:$E,Transactions!$B:$B,">="&$B$6,Transactions!$B:$B,"<="&$B$7,Transactions!$C:$C,"Expense",Transactions!$F:$F,A23) -> 0 | D23: Uber Bolt | E23: =SUMIFS(Transactions!$D:$D,Transactions!$B:$B,">="&$B$6,Transactions!$B:$B,"<="&$B$7,Transactions!$C:$C,"Expense",Transactions!$G:$G,D23) +SUMIFS(Transactions!$E:$E,Transactions!$B:$B,">="&$B$6,Transactions!$B:$B,"<="&$B$7,Transactions!$C:$C,"Expense",Transactions!$G:$G,D23) -> 0
A24: Extended Family | B24: =SUMIFS(Transactions!$D:$D,Transactions!$B:$B,">="&$B$6,Transactions!$B:$B,"<="&$B$7,Transactions!$C:$C,"Expense",Transactions!$F:$F,A24) +SUMIFS(Transactions!$E:$E,Transactions!$B:$B,">="&$B$6,Transactions!$B:$B,"<="&$B$7,Transactions!$C:$C,"Expense",Transactions!$F:$F,A24) -> 2740 | D24: Vehicle maintenance | E24: =SUMIFS(Transactions!$D:$D,Transactions!$B:$B,">="&$B$6,Transactions!$B:$B,"<="&$B$7,Transactions!$C:$C,"Expense",Transactions!$G:$G,D24) +SUMIFS(Transactions!$E:$E,Transactions!$B:$B,">="&$B$6,Transactions!$B:$B,"<="&$B$7,Transactions!$C:$C,"Expense",Transactions!$G:$G,D24) -> 0
A25: Charity | B25: =SUMIFS(Transactions!$D:$D,Transactions!$B:$B,">="&$B$6,Transactions!$B:$B,"<="&$B$7,Transactions!$C:$C,"Expense",Transactions!$F:$F,A25) +SUMIFS(Transactions!$E:$E,Transactions!$B:$B,">="&$B$6,Transactions!$B:$B,"<="&$B$7,Transactions!$C:$C,"Expense",Transactions!$F:$F,A25) -> 1610 | D25: Parking | E25: =SUMIFS(Transactions!$D:$D,Transactions!$B:$B,">="&$B$6,Transactions!$B:$B,"<="&$B$7,Transactions!$C:$C,"Expense",Transactions!$G:$G,D25) +SUMIFS(Transactions!$E:$E,Transactions!$B:$B,">="&$B$6,Transactions!$B:$B,"<="&$B$7,Transactions!$C:$C,"Expense",Transactions!$G:$G,D25) -> 0
A26: Loan Repayment | B26: =SUMIFS(Transactions!$D:$D,Transactions!$B:$B,">="&$B$6,Transactions!$B:$B,"<="&$B$7,Transactions!$C:$C,"Expense",Transactions!$F:$F,A26) +SUMIFS(Transactions!$E:$E,Transactions!$B:$B,">="&$B$6,Transactions!$B:$B,"<="&$B$7,Transactions!$C:$C,"Expense",Transactions!$F:$F,A26) -> 11599 | D26: Rent | E26: =SUMIFS(Transactions!$D:$D,Transactions!$B:$B,">="&$B$6,Transactions!$B:$B,"<="&$B$7,Transactions!$C:$C,"Expense",Transactions!$G:$G,D26) +SUMIFS(Transactions!$E:$E,Transactions!$B:$B,">="&$B$6,Transactions!$B:$B,"<="&$B$7,Transactions!$C:$C,"Expense",Transactions!$G:$G,D26) -> 0
A27: Investment | B27: =SUMIFS(Transactions!$D:$D,Transactions!$B:$B,">="&$B$6,Transactions!$B:$B,"<="&$B$7,Transactions!$C:$C,"Expense",Transactions!$F:$F,A27) +SUMIFS(Transactions!$E:$E,Transactions!$B:$B,">="&$B$6,Transactions!$B:$B,"<="&$B$7,Transactions!$C:$C,"Expense",Transactions!$F:$F,A27) -> 27500 | D27: Electricity | E27: =SUMIFS(Transactions!$D:$D,Transactions!$B:$B,">="&$B$6,Transactions!$B:$B,"<="&$B$7,Transactions!$C:$C,"Expense",Transactions!$G:$G,D27) +SUMIFS(Transactions!$E:$E,Transactions!$B:$B,">="&$B$6,Transactions!$B:$B,"<="&$B$7,Transactions!$C:$C,"Expense",Transactions!$G:$G,D27) -> 0
A28: Other | B28: =SUMIFS(Transactions!$D:$D,Transactions!$B:$B,">="&$B$6,Transactions!$B:$B,"<="&$B$7,Transactions!$C:$C,"Expense",Transactions!$F:$F,A28) +SUMIFS(Transactions!$E:$E,Transactions!$B:$B,">="&$B$6,Transactions!$B:$B,"<="&$B$7,Transactions!$C:$C,"Expense",Transactions!$F:$F,A28) -> 750 | D28: Water | E28: =SUMIFS(Transactions!$D:$D,Transactions!$B:$B,">="&$B$6,Transactions!$B:$B,"<="&$B$7,Transactions!$C:$C,"Expense",Transactions!$G:$G,D28) +SUMIFS(Transactions!$E:$E,Transactions!$B:$B,">="&$B$6,Transactions!$B:$B,"<="&$B$7,Transactions!$C:$C,"Expense",Transactions!$G:$G,D28) -> 0
D29: Internet | E29: =SUMIFS(Transactions!$D:$D,Transactions!$B:$B,">="&$B$6,Transactions!$B:$B,"<="&$B$7,Transactions!$C:$C,"Expense",Transactions!$G:$G,D29) +SUMIFS(Transactions!$E:$E,Transactions!$B:$B,">="&$B$6,Transactions!$B:$B,"<="&$B$7,Transactions!$C:$C,"Expense",Transactions!$G:$G,D29) -> 0
D30: Phone bill | E30: =SUMIFS(Transactions!$D:$D,Transactions!$B:$B,">="&$B$6,Transactions!$B:$B,"<="&$B$7,Transactions!$C:$C,"Expense",Transactions!$G:$G,D30) +SUMIFS(Transactions!$E:$E,Transactions!$B:$B,">="&$B$6,Transactions!$B:$B,"<="&$B$7,Transactions!$C:$C,"Expense",Transactions!$G:$G,D30) -> 0
D31: Gas | E31: =SUMIFS(Transactions!$D:$D,Transactions!$B:$B,">="&$B$6,Transactions!$B:$B,"<="&$B$7,Transactions!$C:$C,"Expense",Transactions!$G:$G,D31) +SUMIFS(Transactions!$E:$E,Transactions!$B:$B,">="&$B$6,Transactions!$B:$B,"<="&$B$7,Transactions!$C:$C,"Expense",Transactions!$G:$G,D31) -> 0
D32: Clothing | E32: =SUMIFS(Transactions!$D:$D,Transactions!$B:$B,">="&$B$6,Transactions!$B:$B,"<="&$B$7,Transactions!$C:$C,"Expense",Transactions!$G:$G,D32) +SUMIFS(Transactions!$E:$E,Transactions!$B:$B,">="&$B$6,Transactions!$B:$B,"<="&$B$7,Transactions!$C:$C,"Expense",Transactions!$G:$G,D32) -> 65
D33: Electronics | E33: =SUMIFS(Transactions!$D:$D,Transactions!$B:$B,">="&$B$6,Transactions!$B:$B,"<="&$B$7,Transactions!$C:$C,"Expense",Transactions!$G:$G,D33) +SUMIFS(Transactions!$E:$E,Transactions!$B:$B,">="&$B$6,Transactions!$B:$B,"<="&$B$7,Transactions!$C:$C,"Expense",Transactions!$G:$G,D33) -> 0
D34: Home goods | E34: =SUMIFS(Transactions!$D:$D,Transactions!$B:$B,">="&$B$6,Transactions!$B:$B,"<="&$B$7,Transactions!$C:$C,"Expense",Transactions!$G:$G,D34) +SUMIFS(Transactions!$E:$E,Transactions!$B:$B,">="&$B$6,Transactions!$B:$B,"<="&$B$7,Transactions!$C:$C,"Expense",Transactions!$G:$G,D34) -> 0
D35: Personal items | E35: =SUMIFS(Transactions!$D:$D,Transactions!$B:$B,">="&$B$6,Transactions!$B:$B,"<="&$B$7,Transactions!$C:$C,"Expense",Transactions!$G:$G,D35) +SUMIFS(Transactions!$E:$E,Transactions!$B:$B,">="&$B$6,Transactions!$B:$B,"<="&$B$7,Transactions!$C:$C,"Expense",Transactions!$G:$G,D35) -> 0
D36: Pharmacy | E36: =SUMIFS(Transactions!$D:$D,Transactions!$B:$B,">="&$B$6,Transactions!$B:$B,"<="&$B$7,Transactions!$C:$C,"Expense",Transactions!$G:$G,D36) +SUMIFS(Transactions!$E:$E,Transactions!$B:$B,">="&$B$6,Transactions!$B:$B,"<="&$B$7,Transactions!$C:$C,"Expense",Transactions!$G:$G,D36) -> 0
D37: Doctor Clinic | E37: =SUMIFS(Transactions!$D:$D,Transactions!$B:$B,">="&$B$6,Transactions!$B:$B,"<="&$B$7,Transactions!$C:$C,"Expense",Transactions!$G:$G,D37) +SUMIFS(Transactions!$E:$E,Transactions!$B:$B,">="&$B$6,Transactions!$B:$B,"<="&$B$7,Transactions!$C:$C,"Expense",Transactions!$G:$G,D37) -> 0
D38: Insurance | E38: =SUMIFS(Transactions!$D:$D,Transactions!$B:$B,">="&$B$6,Transactions!$B:$B,"<="&$B$7,Transactions!$C:$C,"Expense",Transactions!$G:$G,D38) +SUMIFS(Transactions!$E:$E,Transactions!$B:$B,">="&$B$6,Transactions!$B:$B,"<="&$B$7,Transactions!$C:$C,"Expense",Transactions!$G:$G,D38) -> 0
D39: Fitness | E39: =SUMIFS(Transactions!$D:$D,Transactions!$B:$B,">="&$B$6,Transactions!$B:$B,"<="&$B$7,Transactions!$C:$C,"Expense",Transactions!$G:$G,D39) +SUMIFS(Transactions!$E:$E,Transactions!$B:$B,">="&$B$6,Transactions!$B:$B,"<="&$B$7,Transactions!$C:$C,"Expense",Transactions!$G:$G,D39) -> 0
D40: Streaming | E40: =SUMIFS(Transactions!$D:$D,Transactions!$B:$B,">="&$B$6,Transactions!$B:$B,"<="&$B$7,Transactions!$C:$C,"Expense",Transactions!$G:$G,D40) +SUMIFS(Transactions!$E:$E,Transactions!$B:$B,">="&$B$6,Transactions!$B:$B,"<="&$B$7,Transactions!$C:$C,"Expense",Transactions!$G:$G,D40) -> 0
... D54: Unplanned | E54: =SUMIFS(Transactions!$D:$D,Transactions!$B:$B,">="&$B$6,Transactions!$B:$B,"<="&$B$7,Transactions!$C:$C,"Expense",Transactions!$G:$G,D54) +SUMIFS(Transactions!$E:$E,Transactions!$B:$B,">="&$B$6,Transactions!$B:$B,"<="&$B$7,Transactions!$C:$C,"Expense",Transactions!$G:$G,D54) -> 0

Sheet Weekly Detail
A1: Weekly Detail
A2: Year | B2: 2026
A4: Week Start | B4: Week End | C4: Expenses | D4: Income | E4: Transfers | F4: Net
A5: =DATE($B$2,1,1)-WEEKDAY(DATE($B$2,1,1),2)+1 -> 46020 | B5: =A5+6 -> 46026 | C5: =SUMIFS(Transactions!$D:$D,Transactions!$B:$B,">="&A5,Transactions!$B:$B,"<="&B5,Transactions!$C:$C,"Expense") +SUMIFS(Transactions!$E:$E,Transactions!$B:$B,">="&A5,Transactions!$B:$B,"<="&B5,Transactions!$C:$C,"Expense") -> 0 | D5: =SUMIFS(Transactions!$D:$D,Transactions!$B:$B,">="&A5,Transactions!$B:$B,"<="&B5,Transactions!$C:$C,"Income") -> 0 | E5: =SUMIFS(Transactions!$D:$D,Transactions!$B:$B,">="&A5,Transactions!$B:$B,"<="&B5,Transactions!$C:$C,"Transfer") -> 0 | F5: =D5-C5 -> 0
A6: =A5+7 -> 46027 | B6: =A6+6 -> 46033 | C6: =SUMIFS(Transactions!$D:$D,Transactions!$B:$B,">="&A6,Transactions!$B:$B,"<="&B6,Transactions!$C:$C,"Expense") +SUMIFS(Transactions!$E:$E,Transactions!$B:$B,">="&A6,Transactions!$B:$B,"<="&B6,Transactions!$C:$C,"Expense") -> 0 | D6: =SUMIFS(Transactions!$D:$D,Transactions!$B:$B,">="&A6,Transactions!$B:$B,"<="&B6,Transactions!$C:$C,"Income") -> 0 | E6: =SUMIFS(Transactions!$D:$D,Transactions!$B:$B,">="&A6,Transactions!$B:$B,"<="&B6,Transactions!$C:$C,"Transfer") -> 0 | F6: =D6-C6 -> 0
A7: =A6+7 -> 46034 | B7: =A7+6 -> 46040 | C7: =SUMIFS(Transactions!$D:$D,Transactions!$B:$B,">="&A7,Transactions!$B:$B,"<="&B7,Transactions!$C:$C,"Expense") +SUMIFS(Transactions!$E:$E,Transactions!$B:$B,">="&A7,Transactions!$B:$B,"<="&B7,Transactions!$C:$C,"Expense") -> 0 | D7: =SUMIFS(Transactions!$D:$D,Transactions!$B:$B,">="&A7,Transactions!$B:$B,"<="&B7,Transactions!$C:$C,"Income") -> 0 | E7: =SUMIFS(Transactions!$D:$D,Transactions!$B:$B,">="&A7,Transactions!$B:$B,"<="&B7,Transactions!$C:$C,"Transfer") -> 0 | F7: =D7-C7 -> 0
A8: =A7+7 -> 46041 | B8: =A8+6 -> 46047 | C8: =SUMIFS(Transactions!$D:$D,Transactions!$B:$B,">="&A8,Transactions!$B:$B,"<="&B8,Transactions!$C:$C,"Expense") +SUMIFS(Transactions!$E:$E,Transactions!$B:$B,">="&A8,Transactions!$B:$B,"<="&B8,Transactions!$C:$C,"Expense") -> 0 | D8: =SUMIFS(Transactions!$D:$D,Transactions!$B:$B,">="&A8,Transactions!$B:$B,"<="&B8,Transactions!$C:$C,"Income") -> 0 | E8: =SUMIFS(Transactions!$D:$D,Transactions!$B:$B,">="&A8,Transactions!$B:$B,"<="&B8,Transactions!$C:$C,"Transfer") -> 0 | F8: =D8-C8 -> 0
A9: =A8+7 -> 46048 | B9: =A9+6 -> 46054 | C9: =SUMIFS(Transactions!$D:$D,Transactions!$B:$B,">="&A9,Transactions!$B:$B,"<="&B9,Transactions!$C:$C,"Expense") +SUMIFS(Transactions!$E:$E,Transactions!$B:$B,">="&A9,Transactions!$B:$B,"<="&B9,Transactions!$C:$C,"Expense") -> 0 | D9: =SUMIFS(Transactions!$D:$D,Transactions!$B:$B,">="&A9,Transactions!$B:$B,"<="&B9,Transactions!$C:$C,"Income") -> 0 | E9: =SUMIFS(Transactions!$D:$D,Transactions!$B:$B,">="&A9,Transactions!$B:$B,"<="&B9,Transactions!$C:$C,"Transfer") -> 0 | F9: =D9-C9 -> 0
A10: =A9+7 -> 46055 | B10: =A10+6 -> 46061 | C10: =SUMIFS(Transactions!$D:$D,Transactions!$B:$B,">="&A10,Transactions!$B:$B,"<="&B10,Transactions!$C:$C,"Expense") +SUMIFS(Transactions!$E:$E,Transactions!$B:$B,">="&A10,Transactions!$B:$B,"<="&B10,Transactions!$C:$C,"Expense") -> 0 | D10: =SUMIFS(Transactions!$D:$D,Transactions!$B:$B,">="&A10,Transactions!$B:$B,"<="&B10,Transactions!$C:$C,"Income") -> 0 | E10: =SUMIFS(Transactions!$D:$D,Transactions!$B:$B,">="&A10,Transactions!$B:$B,"<="&B10,Transactions!$C:$C,"Transfer") -> 0 | F10: =D10-C10 -> 0
A11: =A10+7 -> 46062 | B11: =A11+6 -> 46068 | C11: =SUMIFS(Transactions!$D:$D,Transactions!$B:$B,">="&A11,Transactions!$B:$B,"<="&B11,Transactions!$C:$C,"Expense") +SUMIFS(Transactions!$E:$E,Transactions!$B:$B,">="&A11,Transactions!$B:$B,"<="&B11,Transactions!$C:$C,"Expense") -> 0 | D11: =SUMIFS(Transactions!$D:$D,Transactions!$B:$B,">="&A11,Transactions!$B:$B,"<="&B11,Transactions!$C:$C,"Income") -> 0 | E11: =SUMIFS(Transactions!$D:$D,Transactions!$B:$B,">="&A11,Transactions!$B:$B,"<="&B11,Transactions!$C:$C,"Transfer") -> 0 | F11: =D11-C11 -> 0
A12: =A11+7 -> 46069 | B12: =A12+6 -> 46075 | C12: =SUMIFS(Transactions!$D:$D,Transactions!$B:$B,">="&A12,Transactions!$B:$B,"<="&B12,Transactions!$C:$C,"Expense") +SUMIFS(Transactions!$E:$E,Transactions!$B:$B,">="&A12,Transactions!$B:$B,"<="&B12,Transactions!$C:$C,"Expense") -> 0 | D12: =SUMIFS(Transactions!$D:$D,Transactions!$B:$B,">="&A12,Transactions!$B:$B,"<="&B12,Transactions!$C:$C,"Income") -> 0 | E12: =SUMIFS(Transactions!$D:$D,Transactions!$B:$B,">="&A12,Transactions!$B:$B,"<="&B12,Transactions!$C:$C,"Transfer") -> 0 | F12: =D12-C12 -> 0
A13: =A12+7 -> 46076 | B13: =A13+6 -> 46082 | C13: =SUMIFS(Transactions!$D:$D,Transactions!$B:$B,">="&A13,Transactions!$B:$B,"<="&B13,Transactions!$C:$C,"Expense") +SUMIFS(Transactions!$E:$E,Transactions!$B:$B,">="&A13,Transactions!$B:$B,"<="&B13,Transactions!$C:$C,"Expense") -> 0 | D13: =SUMIFS(Transactions!$D:$D,Transactions!$B:$B,">="&A13,Transactions!$B:$B,"<="&B13,Transactions!$C:$C,"Income") -> 0 | E13: =SUMIFS(Transactions!$D:$D,Transactions!$B:$B,">="&A13,Transactions!$B:$B,"<="&B13,Transactions!$C:$C,"Transfer") -> 0 | F13: =D13-C13 -> 0
A14: =A13+7 -> 46083 | B14: =A14+6 -> 46089 | C14: =SUMIFS(Transactions!$D:$D,Transactions!$B:$B,">="&A14,Transactions!$B:$B,"<="&B14,Transactions!$C:$C,"Expense") +SUMIFS(Transactions!$E:$E,Transactions!$B:$B,">="&A14,Transactions!$B:$B,"<="&B14,Transactions!$C:$C,"Expense") -> 0 | D14: =SUMIFS(Transactions!$D:$D,Transactions!$B:$B,">="&A14,Transactions!$B:$B,"<="&B14,Transactions!$C:$C,"Income") -> 0 | E14: =SUMIFS(Transactions!$D:$D,Transactions!$B:$B,">="&A14,Transactions!$B:$B,"<="&B14,Transactions!$C:$C,"Transfer") -> 0 | F14: =D14-C14 -> 0
A15: =A14+7 -> 46090 | B15: =A15+6 -> 46096 | C15: =SUMIFS(Transactions!$D:$D,Transactions!$B:$B,">="&A15,Transactions!$B:$B,"<="&B15,Transactions!$C:$C,"Expense") +SUMIFS(Transactions!$E:$E,Transactions!$B:$B,">="&A15,Transactions!$B:$B,"<="&B15,Transactions!$C:$C,"Expense") -> 0 | D15: =SUMIFS(Transactions!$D:$D,Transactions!$B:$B,">="&A15,Transactions!$B:$B,"<="&B15,Transactions!$C:$C,"Income") -> 0 | E15: =SUMIFS(Transactions!$D:$D,Transactions!$B:$B,">="&A15,Transactions!$B:$B,"<="&B15,Transactions!$C:$C,"Transfer") -> 0 | F15: =D15-C15 -> 0
A16: =A15+7 -> 46097 | B16: =A16+6 -> 46103 | C16: =SUMIFS(Transactions!$D:$D,Transactions!$B:$B,">="&A16,Transactions!$B:$B,"<="&B16,Transactions!$C:$C,"Expense") +SUMIFS(Transactions!$E:$E,Transactions!$B:$B,">="&A16,Transactions!$B:$B,"<="&B16,Transactions!$C:$C,"Expense") -> 0 | D16: =SUMIFS(Transactions!$D:$D,Transactions!$B:$B,">="&A16,Transactions!$B:$B,"<="&B16,Transactions!$C:$C,"Income") -> 0 | E16: =SUMIFS(Transactions!$D:$D,Transactions!$B:$B,">="&A16,Transactions!$B:$B,"<="&B16,Transactions!$C:$C,"Transfer") -> 0 | F16: =D16-C16 -> 0
A17: =A16+7 -> 46104 | B17: =A17+6 -> 46110 | C17: =SUMIFS(Transactions!$D:$D,Transactions!$B:$B,">="&A17,Transactions!$B:$B,"<="&B17,Transactions!$C:$C,"Expense") +SUMIFS(Transactions!$E:$E,Transactions!$B:$B,">="&A17,Transactions!$B:$B,"<="&B17,Transactions!$C:$C,"Expense") -> 0 | D17: =SUMIFS(Transactions!$D:$D,Transactions!$B:$B,">="&A17,Transactions!$B:$B,"<="&B17,Transactions!$C:$C,"Income") -> 0 | E17: =SUMIFS(Transactions!$D:$D,Transactions!$B:$B,">="&A17,Transactions!$B:$B,"<="&B17,Transactions!$C:$C,"Transfer") -> 0 | F17: =D17-C17 -> 0
... A58: =A57+7 -> 46391 | B58: =A58+6 -> 46397 | C58: =SUMIFS(Transactions!$D:$D,Transactions!$B:$B,">="&A58,Transactions!$B:$B,"<="&B58,Transactions!$C:$C,"Expense") +SUMIFS(Transactions!$E:$E,Transactions!$B:$B,">="&A58,Transactions!$B:$B,"<="&B58,Transactions!$C:$C,"Expense") -> 0 | D58: =SUMIFS(Transactions!$D:$D,Transactions!$B:$B,">="&A58,Transactions!$B:$B,"<="&B58,Transactions!$C:$C,"Income") -> 0 | E58: =SUMIFS(Transactions!$D:$D,Transactions!$B:$B,">="&A58,Transactions!$B:$B,"<="&B58,Transactions!$C:$C,"Transfer") -> 0 | F58: =D58-C58 -> 0

Sheet Monthly Detail
A1: Monthly Detail
A2: Year | B2: 2026
A4: Month | B4: Start Date | C4: End Date | D4: Expenses | E4: Income | F4: Transfers | G4: Net
A5: Jan | B5: =DATE($B$2,1,1) -> 46023 | C5: =EOMONTH(B5,0) -> 46053 | D5: =SUMIFS(Transactions!$D:$D,Transactions!$B:$B,">="&B5,Transactions!$B:$B,"<="&C5,Transactions!$C:$C,"Expense") +SUMIFS(Transactions!$E:$E,Transactions!$B:$B,">="&B5,Transactions!$B:$B,"<="&C5,Transactions!$C:$C,"Expense") -> 0 | E5: =SUMIFS(Transactions!$D:$D,Transactions!$B:$B,">="&B5,Transactions!$B:$B,"<="&C5,Transactions!$C:$C,"Income") -> 0 | F5: =SUMIFS(Transactions!$D:$D,Transactions!$B:$B,">="&B5,Transactions!$B:$B,"<="&C5,Transactions!$C:$C,"Transfer") -> 0 | G5: =E5-D5 -> 0
A6: Feb | B6: =DATE($B$2,2,1) -> 46054 | C6: =EOMONTH(B6,0) -> 46081 | D6: =SUMIFS(Transactions!$D:$D,Transactions!$B:$B,">="&B6,Transactions!$B:$B,"<="&C6,Transactions!$C:$C,"Expense") +SUMIFS(Transactions!$E:$E,Transactions!$B:$B,">="&B6,Transactions!$B:$B,"<="&C6,Transactions!$C:$C,"Expense") -> 0 | E6: =SUMIFS(Transactions!$D:$D,Transactions!$B:$B,">="&B6,Transactions!$B:$B,"<="&C6,Transactions!$C:$C,"Income") -> 0 | F6: =SUMIFS(Transactions!$D:$D,Transactions!$B:$B,">="&B6,Transactions!$B:$B,"<="&C6,Transactions!$C:$C,"Transfer") -> 0 | G6: =E6-D6 -> 0
A7: Mar | B7: =DATE($B$2,3,1) -> 46082 | C7: =EOMONTH(B7,0) -> 46112 | D7: =SUMIFS(Transactions!$D:$D,Transactions!$B:$B,">="&B7,Transactions!$B:$B,"<="&C7,Transactions!$C:$C,"Expense") +SUMIFS(Transactions!$E:$E,Transactions!$B:$B,">="&B7,Transactions!$B:$B,"<="&C7,Transactions!$C:$C,"Expense") -> 0 | E7: =SUMIFS(Transactions!$D:$D,Transactions!$B:$B,">="&B7,Transactions!$B:$B,"<="&C7,Transactions!$C:$C,"Income") -> 0 | F7: =SUMIFS(Transactions!$D:$D,Transactions!$B:$B,">="&B7,Transactions!$B:$B,"<="&C7,Transactions!$C:$C,"Transfer") -> 0 | G7: =E7-D7 -> 0
A8: Apr | B8: =DATE($B$2,4,1) -> 46113 | C8: =EOMONTH(B8,0) -> 46142 | D8: =SUMIFS(Transactions!$D:$D,Transactions!$B:$B,">="&B8,Transactions!$B:$B,"<="&C8,Transactions!$C:$C,"Expense") +SUMIFS(Transactions!$E:$E,Transactions!$B:$B,">="&B8,Transactions!$B:$B,"<="&C8,Transactions!$C:$C,"Expense") -> 0 | E8: =SUMIFS(Transactions!$D:$D,Transactions!$B:$B,">="&B8,Transactions!$B:$B,"<="&C8,Transactions!$C:$C,"Income") -> 0 | F8: =SUMIFS(Transactions!$D:$D,Transactions!$B:$B,">="&B8,Transactions!$B:$B,"<="&C8,Transactions!$C:$C,"Transfer") -> 0 | G8: =E8-D8 -> 0
A9: May | B9: =DATE($B$2,5,1) -> 46143 | C9: =EOMONTH(B9,0) -> 46173 | D9: =SUMIFS(Transactions!$D:$D,Transactions!$B:$B,">="&B9,Transactions!$B:$B,"<="&C9,Transactions!$C:$C,"Expense") +SUMIFS(Transactions!$E:$E,Transactions!$B:$B,">="&B9,Transactions!$B:$B,"<="&C9,Transactions!$C:$C,"Expense") -> 36431 | E9: =SUMIFS(Transactions!$D:$D,Transactions!$B:$B,">="&B9,Transactions!$B:$B,"<="&C9,Transactions!$C:$C,"Income") -> 18847 | F9: =SUMIFS(Transactions!$D:$D,Transactions!$B:$B,">="&B9,Transactions!$B:$B,"<="&C9,Transactions!$C:$C,"Transfer") -> 0 | G9: =E9-D9 -> -17584
A10: Jun | B10: =DATE($B$2,6,1) -> 46174 | C10: =EOMONTH(B10,0) -> 46203 | D10: =SUMIFS(Transactions!$D:$D,Transactions!$B:$B,">="&B10,Transactions!$B:$B,"<="&C10,Transactions!$C:$C,"Expense") +SUMIFS(Transactions!$E:$E,Transactions!$B:$B,">="&B10,Transactions!$B:$B,"<="&C10,Transactions!$C:$C,"Expense") -> 12262 | E10: =SUMIFS(Transactions!$D:$D,Transactions!$B:$B,">="&B10,Transactions!$B:$B,"<="&C10,Transactions!$C:$C,"Income") -> 31042.47 | F10: =SUMIFS(Transactions!$D:$D,Transactions!$B:$B,">="&B10,Transactions!$B:$B,"<="&C10,Transactions!$C:$C,"Transfer") -> 10611 | G10: =E10-D10 -> 18780.47
A11: Jul | B11: =DATE($B$2,7,1) -> 46204 | C11: =EOMONTH(B11,0) -> 46234 | D11: =SUMIFS(Transactions!$D:$D,Transactions!$B:$B,">="&B11,Transactions!$B:$B,"<="&C11,Transactions!$C:$C,"Expense") +SUMIFS(Transactions!$E:$E,Transactions!$B:$B,">="&B11,Transactions!$B:$B,"<="&C11,Transactions!$C:$C,"Expense") -> 250 | E11: =SUMIFS(Transactions!$D:$D,Transactions!$B:$B,">="&B11,Transactions!$B:$B,"<="&C11,Transactions!$C:$C,"Income") -> 0 | F11: =SUMIFS(Transactions!$D:$D,Transactions!$B:$B,">="&B11,Transactions!$B:$B,"<="&C11,Transactions!$C:$C,"Transfer") -> 0 | G11: =E11-D11 -> -250
A12: Aug | B12: =DATE($B$2,8,1) -> 46235 | C12: =EOMONTH(B12,0) -> 46265 | D12: =SUMIFS(Transactions!$D:$D,Transactions!$B:$B,">="&B12,Transactions!$B:$B,"<="&C12,Transactions!$C:$C,"Expense") +SUMIFS(Transactions!$E:$E,Transactions!$B:$B,">="&B12,Transactions!$B:$B,"<="&C12,Transactions!$C:$C,"Expense") -> 0 | E12: =SUMIFS(Transactions!$D:$D,Transactions!$B:$B,">="&B12,Transactions!$B:$B,"<="&C12,Transactions!$C:$C,"Income") -> 0 | F12: =SUMIFS(Transactions!$D:$D,Transactions!$B:$B,">="&B12,Transactions!$B:$B,"<="&C12,Transactions!$C:$C,"Transfer") -> 0 | G12: =E12-D12 -> 0
A13: Sep | B13: =DATE($B$2,9,1) -> 46266 | C13: =EOMONTH(B13,0) -> 46295 | D13: =SUMIFS(Transactions!$D:$D,Transactions!$B:$B,">="&B13,Transactions!$B:$B,"<="&C13,Transactions!$C:$C,"Expense") +SUMIFS(Transactions!$E:$E,Transactions!$B:$B,">="&B13,Transactions!$B:$B,"<="&C13,Transactions!$C:$C,"Expense") -> 0 | E13: =SUMIFS(Transactions!$D:$D,Transactions!$B:$B,">="&B13,Transactions!$B:$B,"<="&C13,Transactions!$C:$C,"Income") -> 0 | F13: =SUMIFS(Transactions!$D:$D,Transactions!$B:$B,">="&B13,Transactions!$B:$B,"<="&C13,Transactions!$C:$C,"Transfer") -> 0 | G13: =E13-D13 -> 0
A14: Oct | B14: =DATE($B$2,10,1) -> 46296 | C14: =EOMONTH(B14,0) -> 46326 | D14: =SUMIFS(Transactions!$D:$D,Transactions!$B:$B,">="&B14,Transactions!$B:$B,"<="&C14,Transactions!$C:$C,"Expense") +SUMIFS(Transactions!$E:$E,Transactions!$B:$B,">="&B14,Transactions!$B:$B,"<="&C14,Transactions!$C:$C,"Expense") -> 0 | E14: =SUMIFS(Transactions!$D:$D,Transactions!$B:$B,">="&B14,Transactions!$B:$B,"<="&C14,Transactions!$C:$C,"Income") -> 0 | F14: =SUMIFS(Transactions!$D:$D,Transactions!$B:$B,">="&B14,Transactions!$B:$B,"<="&C14,Transactions!$C:$C,"Transfer") -> 0 | G14: =E14-D14 -> 0
A15: Nov | B15: =DATE($B$2,11,1) -> 46327 | C15: =EOMONTH(B15,0) -> 46356 | D15: =SUMIFS(Transactions!$D:$D,Transactions!$B:$B,">="&B15,Transactions!$B:$B,"<="&C15,Transactions!$C:$C,"Expense") +SUMIFS(Transactions!$E:$E,Transactions!$B:$B,">="&B15,Transactions!$B:$B,"<="&C15,Transactions!$C:$C,"Expense") -> 0 | E15: =SUMIFS(Transactions!$D:$D,Transactions!$B:$B,">="&B15,Transactions!$B:$B,"<="&C15,Transactions!$C:$C,"Income") -> 0 | F15: =SUMIFS(Transactions!$D:$D,Transactions!$B:$B,">="&B15,Transactions!$B:$B,"<="&C15,Transactions!$C:$C,"Transfer") -> 0 | G15: =E15-D15 -> 0
A16: Dec | B16: =DATE($B$2,12,1) -> 46357 | C16: =EOMONTH(B16,0) -> 46387 | D16: =SUMIFS(Transactions!$D:$D,Transactions!$B:$B,">="&B16,Transactions!$B:$B,"<="&C16,Transactions!$C:$C,"Expense") +SUMIFS(Transactions!$E:$E,Transactions!$B:$B,">="&B16,Transactions!$B:$B,"<="&C16,Transactions!$C:$C,"Expense") -> 0 | E16: =SUMIFS(Transactions!$D:$D,Transactions!$B:$B,">="&B16,Transactions!$B:$B,"<="&C16,Transactions!$C:$C,"Income") -> 0 | F16: =SUMIFS(Transactions!$D:$D,Transactions!$B:$B,">="&B16,Transactions!$B:$B,"<="&C16,Transactions!$C:$C,"Transfer") -> 0 | G16: =E16-D16 -> 0

Sheet Quarterly Detail
A1: Quarterly Detail
A2: Year | B2: 2026
A4: Quarter | B4: Start Date | C4: End Date | D4: Expenses | E4: Income | F4: Transfers | G4: Net
A5: Q1 | B5: =DATE($B$2,1,1) -> 46023 | C5: =EOMONTH(B5,2) -> 46112 | D5: =SUMIFS(Transactions!$D:$D,Transactions!$B:$B,">="&B5,Transactions!$B:$B,"<="&C5,Transactions!$C:$C,"Expense") +SUMIFS(Transactions!$E:$E,Transactions!$B:$B,">="&B5,Transactions!$B:$B,"<="&C5,Transactions!$C:$C,"Expense") -> 0 | E5: =SUMIFS(Transactions!$D:$D,Transactions!$B:$B,">="&B5,Transactions!$B:$B,"<="&C5,Transactions!$C:$C,"Income") -> 0 | F5: =SUMIFS(Transactions!$D:$D,Transactions!$B:$B,">="&B5,Transactions!$B:$B,"<="&C5,Transactions!$C:$C,"Transfer") -> 0 | G5: =E5-D5 -> 0
A6: Q2 | B6: =DATE($B$2,4,1) -> 46113 | C6: =EOMONTH(B6,2) -> 46203 | D6: =SUMIFS(Transactions!$D:$D,Transactions!$B:$B,">="&B6,Transactions!$B:$B,"<="&C6,Transactions!$C:$C,"Expense") +SUMIFS(Transactions!$E:$E,Transactions!$B:$B,">="&B6,Transactions!$B:$B,"<="&C6,Transactions!$C:$C,"Expense") -> 48693 | E6: =SUMIFS(Transactions!$D:$D,Transactions!$B:$B,">="&B6,Transactions!$B:$B,"<="&C6,Transactions!$C:$C,"Income") -> 49889.47 | F6: =SUMIFS(Transactions!$D:$D,Transactions!$B:$B,">="&B6,Transactions!$B:$B,"<="&C6,Transactions!$C:$C,"Transfer") -> 10611 | G6: =E6-D6 -> 1196.47
A7: Q3 | B7: =DATE($B$2,7,1) -> 46204 | C7: =EOMONTH(B7,2) -> 46295 | D7: =SUMIFS(Transactions!$D:$D,Transactions!$B:$B,">="&B7,Transactions!$B:$B,"<="&C7,Transactions!$C:$C,"Expense") +SUMIFS(Transactions!$E:$E,Transactions!$B:$B,">="&B7,Transactions!$B:$B,"<="&C7,Transactions!$C:$C,"Expense") -> 250 | E7: =SUMIFS(Transactions!$D:$D,Transactions!$B:$B,">="&B7,Transactions!$B:$B,"<="&C7,Transactions!$C:$C,"Income") -> 0 | F7: =SUMIFS(Transactions!$D:$D,Transactions!$B:$B,">="&B7,Transactions!$B:$B,"<="&C7,Transactions!$C:$C,"Transfer") -> 0 | G7: =E7-D7 -> -250
A8: Q4 | B8: =DATE($B$2,10,1) -> 46296 | C8: =EOMONTH(B8,2) -> 46387 | D8: =SUMIFS(Transactions!$D:$D,Transactions!$B:$B,">="&B8,Transactions!$B:$B,"<="&C8,Transactions!$C:$C,"Expense") +SUMIFS(Transactions!$E:$E,Transactions!$B:$B,">="&B8,Transactions!$B:$B,"<="&C8,Transactions!$C:$C,"Expense") -> 0 | E8: =SUMIFS(Transactions!$D:$D,Transactions!$B:$B,">="&B8,Transactions!$B:$B,"<="&C8,Transactions!$C:$C,"Income") -> 0 | F8: =SUMIFS(Transactions!$D:$D,Transactions!$B:$B,">="&B8,Transactions!$B:$B,"<="&C8,Transactions!$C:$C,"Transfer") -> 0 | G8: =E8-D8 -> 0

Sheet Yearly Detail
A1: Yearly Detail
A4: Year | B4: Start Date | C4: End Date | D4: Expenses | E4: Income | F4: Transfers | G4: Net
A5: 2024 | B5: =DATE(A5,1,1) -> 45292 | C5: =DATE(A5,12,31) -> 45657 | D5: =SUMIFS(Transactions!$D:$D,Transactions!$B:$B,">="&B5,Transactions!$B:$B,"<="&C5,Transactions!$C:$C,"Expense") +SUMIFS(Transactions!$E:$E,Transactions!$B:$B,">="&B5,Transactions!$B:$B,"<="&C5,Transactions!$C:$C,"Expense") -> 0 | E5: =SUMIFS(Transactions!$D:$D,Transactions!$B:$B,">="&B5,Transactions!$B:$B,"<="&C5,Transactions!$C:$C,"Income") -> 0 | F5: =SUMIFS(Transactions!$D:$D,Transactions!$B:$B,">="&B5,Transactions!$B:$B,"<="&C5,Transactions!$C:$C,"Transfer") -> 0 | G5: =E5-D5 -> 0
A6: 2025 | B6: =DATE(A6,1,1) -> 45658 | C6: =DATE(A6,12,31) -> 46022 | D6: =SUMIFS(Transactions!$D:$D,Transactions!$B:$B,">="&B6,Transactions!$B:$B,"<="&C6,Transactions!$C:$C,"Expense") +SUMIFS(Transactions!$E:$E,Transactions!$B:$B,">="&B6,Transactions!$B:$B,"<="&C6,Transactions!$C:$C,"Expense") -> 0 | E6: =SUMIFS(Transactions!$D:$D,Transactions!$B:$B,">="&B6,Transactions!$B:$B,"<="&C6,Transactions!$C:$C,"Income") -> 0 | F6: =SUMIFS(Transactions!$D:$D,Transactions!$B:$B,">="&B6,Transactions!$B:$B,"<="&C6,Transactions!$C:$C,"Transfer") -> 0 | G6: =E6-D6 -> 0
A7: 2026 | B7: =DATE(A7,1,1) -> 46023 | C7: =DATE(A7,12,31) -> 46387 | D7: =SUMIFS(Transactions!$D:$D,Transactions!$B:$B,">="&B7,Transactions!$B:$B,"<="&C7,Transactions!$C:$C,"Expense") +SUMIFS(Transactions!$E:$E,Transactions!$B:$B,">="&B7,Transactions!$B:$B,"<="&C7,Transactions!$C:$C,"Expense") -> 48943 | E7: =SUMIFS(Transactions!$D:$D,Transactions!$B:$B,">="&B7,Transactions!$B:$B,"<="&C7,Transactions!$C:$C,"Income") -> 49889.47 | F7: =SUMIFS(Transactions!$D:$D,Transactions!$B:$B,">="&B7,Transactions!$B:$B,"<="&C7,Transactions!$C:$C,"Transfer") -> 10611 | G7: =E7-D7 -> 946.47
A8: 2027 | B8: =DATE(A8,1,1) -> 46388 | C8: =DATE(A8,12,31) -> 46752 | D8: =SUMIFS(Transactions!$D:$D,Transactions!$B:$B,">="&B8,Transactions!$B:$B,"<="&C8,Transactions!$C:$C,"Expense") +SUMIFS(Transactions!$E:$E,Transactions!$B:$B,">="&B8,Transactions!$B:$B,"<="&C8,Transactions!$C:$C,"Expense") -> 0 | E8: =SUMIFS(Transactions!$D:$D,Transactions!$B:$B,">="&B8,Transactions!$B:$B,"<="&C8,Transactions!$C:$C,"Income") -> 0 | F8: =SUMIFS(Transactions!$D:$D,Transactions!$B:$B,">="&B8,Transactions!$B:$B,"<="&C8,Transactions!$C:$C,"Transfer") -> 0 | G8: =E8-D8 -> 0
A9: 2028 | B9: =DATE(A9,1,1) -> 46753 | C9: =DATE(A9,12,31) -> 47118 | D9: =SUMIFS(Transactions!$D:$D,Transactions!$B:$B,">="&B9,Transactions!$B:$B,"<="&C9,Transactions!$C:$C,"Expense") +SUMIFS(Transactions!$E:$E,Transactions!$B:$B,">="&B9,Transactions!$B:$B,"<="&C9,Transactions!$C:$C,"Expense") -> 0 | E9: =SUMIFS(Transactions!$D:$D,Transactions!$B:$B,">="&B9,Transactions!$B:$B,"<="&C9,Transactions!$C:$C,"Income") -> 0 | F9: =SUMIFS(Transactions!$D:$D,Transactions!$B:$B,">="&B9,Transactions!$B:$B,"<="&C9,Transactions!$C:$C,"Transfer") -> 0 | G9: =E9-D9 -> 0
A10: 2029 | B10: =DATE(A10,1,1) -> 47119 | C10: =DATE(A10,12,31) -> 47483 | D10: =SUMIFS(Transactions!$D:$D,Transactions!$B:$B,">="&B10,Transactions!$B:$B,"<="&C10,Transactions!$C:$C,"Expense") +SUMIFS(Transactions!$E:$E,Transactions!$B:$B,">="&B10,Transactions!$B:$B,"<="&C10,Transactions!$C:$C,"Expense") -> 0 | E10: =SUMIFS(Transactions!$D:$D,Transactions!$B:$B,">="&B10,Transactions!$B:$B,"<="&C10,Transactions!$C:$C,"Income") -> 0 | F10: =SUMIFS(Transactions!$D:$D,Transactions!$B:$B,">="&B10,Transactions!$B:$B,"<="&C10,Transactions!$C:$C,"Transfer") -> 0 | G10: =E10-D10 -> 0
A11: 2030 | B11: =DATE(A11,1,1) -> 47484 | C11: =DATE(A11,12,31) -> 47848 | D11: =SUMIFS(Transactions!$D:$D,Transactions!$B:$B,">="&B11,Transactions!$B:$B,"<="&C11,Transactions!$C:$C,"Expense") +SUMIFS(Transactions!$E:$E,Transactions!$B:$B,">="&B11,Transactions!$B:$B,"<="&C11,Transactions!$C:$C,"Expense") -> 0 | E11: =SUMIFS(Transactions!$D:$D,Transactions!$B:$B,">="&B11,Transactions!$B:$B,"<="&C11,Transactions!$C:$C,"Income") -> 0 | F11: =SUMIFS(Transactions!$D:$D,Transactions!$B:$B,">="&B11,Transactions!$B:$B,"<="&C11,Transactions!$C:$C,"Transfer") -> 0 | G11: =E11-D11 -> 0

Sheet Validation
A1: ExpenseCategories | B1: IncomeCategories | C1: TransferOnly | D1: BlankList | E1: PaymentMethods | F1: Accounts | G1: Types | H1: MonthOptions | I1: QuarterOptions | J1: YearOptions | K1: WeekOptions | M1: Food_Drink_Expense | N1: Transport_Expense | O1: Bills_Utilities_Expense | P1: Shopping_Expense | Q1: Health_Expense | R1: Entertainment_Expense | S1: Personal_Expense | T1: Family_Home_Expense | U1: Other_Expense | V1: Salary_Income | W1: Side_Income_Income | X1: Gifts_Income | Y1: Refunds_Income | Z1: Other_Income_Income
A2: Food Drink | B2: Salary | C2: Transfer | E2: Cash | F2: Ecobank | G2: Expense | H2: Jan | I2: Q1 | J2: Full Year | K2: 45292 | M2: Groceries | N2: Fuel | O2: Rent | P2: Clothing | Q2: Pharmacy | R2: Streaming | S2: Hair Beauty | T2: Family support | U2: Miscellaneous | V2: Main job | W2: Freelance | X2: Family Friends | Y2: Purchase refund | Z2: Other
A3: Transport | B3: Side Income | E3: Mobile Money | F3: GCB | G3: Income | H3: Feb | I3: Q2 | K3: 45299 | M3: Restaurants | N3: Taxi Trotro | O3: Electricity | P3: Electronics | Q3: Doctor Clinic | R3: Events Outings | S3: Gifts | T3: Childcare | U3: Bank fees | V3: Bonus | W3: Business | Y3: Reimbursement
A4: Bills Utilities | B4: Gifts | E4: Card | F4: MoMo Wallet | G4: Transfer | H4: Mar | I4: Q3 | K4: 45306 | M4: Takeaway | N4: Uber Bolt | O4: Water | P4: Home goods | Q4: Insurance | R4: Movies | S4: Education | T4: Household help | U4: Unplanned
A5: Shopping | B5: Refunds | E5: Bank Transfer | F5: Cash | H5: Apr | I5: Q4 | K5: 45313 | M5: Coffee Snacks | N5: Vehicle maintenance | O5: Internet | P5: Personal items | Q5: Fitness | R5: Hobbies | S5: Donations
A6: Health | B6: Other Income | E6: Other | F6: Other | H6: May | K6: 45320 | N6: Parking | O6: Phone bill
A7: Entertainment | H7: Jun | K7: 45327 | O7: Gas
A8: Personal | H8: Jul | K8: 45334
A9: Family Home | H9: Aug | K9: 45341
A10: Other | H10: Sep | K10: 45348
H11: Oct | K11: 45355
H12: Nov | K12: 45362
H13: Dec | K13: 45369
K14: 45376
K15: 45383
K16: 45390
K17: 45397
K18: 45404
K19: 45411
K20: 45418
K21: 45425
K22: 45432
K23: 45439
K24: 45446
K25: 45453
... K367: 47847
